2024-12-09 01:09:13,032:ERRORsearch-appError occured: 330 is not in list
Traceback (most recent call last):
  File "C:\Users\dimdr\Coding Factory\Courses\Python\python-cf6\chapter05\18_logging_app.py", line 25, in main
    index = nums.index(330)
            ^^^^^^^^^^^^^^^
ValueError: 330 is not in list
